[2023-12-12T01:14:20.286+0000] {taskinstance.py:1159} INFO - Dependencies all met for dep_context=non-requeueable deps ti=<TaskInstance: dag_openaq_catchup.load_measures_data scheduled__2023-12-07T00:00:00+00:00 [queued]>
[2023-12-12T01:14:20.581+0000] {taskinstance.py:1159} INFO - Dependencies all met for dep_context=requeueable deps ti=<TaskInstance: dag_openaq_catchup.load_measures_data scheduled__2023-12-07T00:00:00+00:00 [queued]>
[2023-12-12T01:14:20.595+0000] {taskinstance.py:1361} INFO - Starting attempt 1 of 4
[2023-12-12T01:14:21.425+0000] {taskinstance.py:1382} INFO - Executing <Task(PythonOperator): load_measures_data> on 2023-12-07 00:00:00+00:00
[2023-12-12T01:14:21.586+0000] {standard_task_runner.py:57} INFO - Started process 318 to run task
[2023-12-12T01:14:21.643+0000] {standard_task_runner.py:84} INFO - Running: ['***', 'tasks', 'run', 'dag_openaq_catchup', 'load_measures_data', 'scheduled__2023-12-07T00:00:00+00:00', '--job-id', '324', '--raw', '--subdir', 'DAGS_FOLDER/dag_openaq_catchup.py', '--cfg-path', '/tmp/tmpfipbj57x']
[2023-12-12T01:14:21.658+0000] {standard_task_runner.py:85} INFO - Job 324: Subtask load_measures_data
[2023-12-12T01:14:22.974+0000] {task_command.py:416} INFO - Running <TaskInstance: dag_openaq_catchup.load_measures_data scheduled__2023-12-07T00:00:00+00:00 [running]> on host 1a187d37aaef
[2023-12-12T01:14:26.065+0000] {taskinstance.py:1662} INFO - Exporting env vars: AIRFLOW_CTX_DAG_OWNER='***' AIRFLOW_CTX_DAG_ID='dag_openaq_catchup' AIRFLOW_CTX_TASK_ID='load_measures_data' AIRFLOW_CTX_EXECUTION_DATE='2023-12-07T00:00:00+00:00' AIRFLOW_CTX_TRY_NUMBER='1' AIRFLOW_CTX_DAG_RUN_ID='scheduled__2023-12-07T00:00:00+00:00'
[2023-12-12T01:14:26.212+0000] {main.py:140} INFO - Archivo de configuracion leido correctamente.
[2023-12-12T01:14:26.219+0000] {utils.py:25} INFO - Obteniendo datos de https://api.openaq.org/v2/measurements...
[2023-12-12T01:14:34.554+0000] {utils.py:39} ERROR - La peticion ha fallado. Codigo del error: HTTPSConnectionPool(host='api.openaq.org', port=443): Max retries exceeded with url: /v2/measurements?date_from=2023-12-07T00%3A00%3A00&date_to=2023-12-08T00%3A00%3A00 (Caused by NewConnectionError('<urllib3.connection.HTTPSConnection object at 0xffff97134670>: Failed to establish a new connection: [Errno -3] Temporary failure in name resolution'))
[2023-12-12T01:14:34.756+0000] {taskinstance.py:1937} ERROR - Task failed with exception
Traceback (most recent call last):
  File "/home/airflow/.local/lib/python3.8/site-packages/urllib3/connection.py", line 174, in _new_conn
    conn = connection.create_connection(
  File "/home/airflow/.local/lib/python3.8/site-packages/urllib3/util/connection.py", line 72, in create_connection
    for res in socket.getaddrinfo(host, port, family, socket.SOCK_STREAM):
  File "/usr/local/lib/python3.8/socket.py", line 918, in getaddrinfo
    for res in _socket.getaddrinfo(host, port, family, type, proto, flags):
socket.gaierror: [Errno -3] Temporary failure in name resolution

During handling of the above exception, another exception occurred:

Traceback (most recent call last):
  File "/home/airflow/.local/lib/python3.8/site-packages/urllib3/connectionpool.py", line 715, in urlopen
    httplib_response = self._make_request(
  File "/home/airflow/.local/lib/python3.8/site-packages/urllib3/connectionpool.py", line 404, in _make_request
    self._validate_conn(conn)
  File "/home/airflow/.local/lib/python3.8/site-packages/urllib3/connectionpool.py", line 1058, in _validate_conn
    conn.connect()
  File "/home/airflow/.local/lib/python3.8/site-packages/urllib3/connection.py", line 363, in connect
    self.sock = conn = self._new_conn()
  File "/home/airflow/.local/lib/python3.8/site-packages/urllib3/connection.py", line 186, in _new_conn
    raise NewConnectionError(
urllib3.exceptions.NewConnectionError: <urllib3.connection.HTTPSConnection object at 0xffff97134670>: Failed to establish a new connection: [Errno -3] Temporary failure in name resolution

During handling of the above exception, another exception occurred:

Traceback (most recent call last):
  File "/home/airflow/.local/lib/python3.8/site-packages/requests/adapters.py", line 486, in send
    resp = conn.urlopen(
  File "/home/airflow/.local/lib/python3.8/site-packages/urllib3/connectionpool.py", line 799, in urlopen
    retries = retries.increment(
  File "/home/airflow/.local/lib/python3.8/site-packages/urllib3/util/retry.py", line 592, in increment
    raise MaxRetryError(_pool, url, error or ResponseError(cause))
urllib3.exceptions.MaxRetryError: HTTPSConnectionPool(host='api.openaq.org', port=443): Max retries exceeded with url: /v2/measurements?date_from=2023-12-07T00%3A00%3A00&date_to=2023-12-08T00%3A00%3A00 (Caused by NewConnectionError('<urllib3.connection.HTTPSConnection object at 0xffff97134670>: Failed to establish a new connection: [Errno -3] Temporary failure in name resolution'))

During handling of the above exception, another exception occurred:

Traceback (most recent call last):
  File "/opt/airflow/scripts/utils.py", line 26, in get_data
    response = requests.get(
  File "/home/airflow/.local/lib/python3.8/site-packages/requests/api.py", line 73, in get
    return request("get", url, params=params, **kwargs)
  File "/home/airflow/.local/lib/python3.8/site-packages/requests/api.py", line 59, in request
    return session.request(method=method, url=url, **kwargs)
  File "/home/airflow/.local/lib/python3.8/site-packages/requests/sessions.py", line 589, in request
    resp = self.send(prep, **send_kwargs)
  File "/home/airflow/.local/lib/python3.8/site-packages/requests/sessions.py", line 703, in send
    r = adapter.send(request, **kwargs)
  File "/home/airflow/.local/lib/python3.8/site-packages/requests/adapters.py", line 519, in send
    raise ConnectionError(e, request=request)
requests.exceptions.ConnectionError: HTTPSConnectionPool(host='api.openaq.org', port=443): Max retries exceeded with url: /v2/measurements?date_from=2023-12-07T00%3A00%3A00&date_to=2023-12-08T00%3A00%3A00 (Caused by NewConnectionError('<urllib3.connection.HTTPSConnection object at 0xffff97134670>: Failed to establish a new connection: [Errno -3] Temporary failure in name resolution'))

During handling of the above exception, another exception occurred:

Traceback (most recent call last):
  File "/home/airflow/.local/lib/python3.8/site-packages/airflow/operators/python.py", line 192, in execute
    return_value = self.execute_callable()
  File "/home/airflow/.local/lib/python3.8/site-packages/airflow/operators/python.py", line 209, in execute_callable
    return self.python_callable(*self.op_args, **self.op_kwargs)
  File "/opt/airflow/scripts/main.py", line 152, in load_measures
    json_api = get_data(base_url, endpoint, headers, params=params)
  File "/opt/airflow/scripts/utils.py", line 40, in get_data
    raise Exception(f"La peticion ha fallado. Codigo del error: {e}")
Exception: La peticion ha fallado. Codigo del error: HTTPSConnectionPool(host='api.openaq.org', port=443): Max retries exceeded with url: /v2/measurements?date_from=2023-12-07T00%3A00%3A00&date_to=2023-12-08T00%3A00%3A00 (Caused by NewConnectionError('<urllib3.connection.HTTPSConnection object at 0xffff97134670>: Failed to establish a new connection: [Errno -3] Temporary failure in name resolution'))
[2023-12-12T01:14:35.928+0000] {taskinstance.py:1400} INFO - Marking task as UP_FOR_RETRY. dag_id=dag_openaq_catchup, task_id=load_measures_data, execution_date=20231207T000000, start_date=20231212T011420, end_date=20231212T011435
[2023-12-12T01:14:36.060+0000] {standard_task_runner.py:104} ERROR - Failed to execute job 324 for task load_measures_data (La peticion ha fallado. Codigo del error: HTTPSConnectionPool(host='api.openaq.org', port=443): Max retries exceeded with url: /v2/measurements?date_from=2023-12-07T00%3A00%3A00&date_to=2023-12-08T00%3A00%3A00 (Caused by NewConnectionError('<urllib3.connection.HTTPSConnection object at 0xffff97134670>: Failed to establish a new connection: [Errno -3] Temporary failure in name resolution')); 318)
[2023-12-12T01:14:36.170+0000] {local_task_job_runner.py:228} INFO - Task exited with return code 1
[2023-12-12T01:14:36.751+0000] {taskinstance.py:2778} INFO - 0 downstream tasks scheduled from follow-on schedule check
