[2023-12-05T22:00:03.896+0000] {taskinstance.py:1159} INFO - Dependencies all met for dep_context=non-requeueable deps ti=<TaskInstance: dag_openaq.load_stations_data scheduled__2023-12-05T21:00:00+00:00 [queued]>
[2023-12-05T22:00:03.901+0000] {taskinstance.py:1159} INFO - Dependencies all met for dep_context=requeueable deps ti=<TaskInstance: dag_openaq.load_stations_data scheduled__2023-12-05T21:00:00+00:00 [queued]>
[2023-12-05T22:00:03.902+0000] {taskinstance.py:1361} INFO - Starting attempt 1 of 4
[2023-12-05T22:00:03.911+0000] {taskinstance.py:1382} INFO - Executing <Task(PythonOperator): load_stations_data> on 2023-12-05 21:00:00+00:00
[2023-12-05T22:00:03.917+0000] {standard_task_runner.py:57} INFO - Started process 792 to run task
[2023-12-05T22:00:03.923+0000] {standard_task_runner.py:84} INFO - Running: ['***', 'tasks', 'run', 'dag_openaq', 'load_stations_data', 'scheduled__2023-12-05T21:00:00+00:00', '--job-id', '281', '--raw', '--subdir', 'DAGS_FOLDER/dag_openaq.py', '--cfg-path', '/tmp/tmpmgqg_8o0']
[2023-12-05T22:00:03.925+0000] {standard_task_runner.py:85} INFO - Job 281: Subtask load_stations_data
[2023-12-05T22:00:03.967+0000] {task_command.py:416} INFO - Running <TaskInstance: dag_openaq.load_stations_data scheduled__2023-12-05T21:00:00+00:00 [running]> on host 01a38cb1bd44
[2023-12-05T22:00:04.016+0000] {taskinstance.py:1662} INFO - Exporting env vars: AIRFLOW_CTX_DAG_OWNER='***' AIRFLOW_CTX_DAG_ID='dag_openaq' AIRFLOW_CTX_TASK_ID='load_stations_data' AIRFLOW_CTX_EXECUTION_DATE='2023-12-05T21:00:00+00:00' AIRFLOW_CTX_TRY_NUMBER='1' AIRFLOW_CTX_DAG_RUN_ID='scheduled__2023-12-05T21:00:00+00:00'
[2023-12-05T22:00:04.018+0000] {main.py:22} INFO - Archivo de configuracion leido correctamente.
[2023-12-05T22:00:04.018+0000] {utils.py:25} INFO - Obteniendo datos de https://api.openaq.org/v2/locations...
[2023-12-05T22:00:10.686+0000] {utils.py:39} ERROR - La peticion ha fallado. Codigo del error: 408 Client Error: Request Time-out for url: https://api.openaq.org/v2/locations?limit=2500
[2023-12-05T22:00:10.689+0000] {taskinstance.py:1937} ERROR - Task failed with exception
Traceback (most recent call last):
  File "/opt/airflow/scripts/utils.py", line 29, in get_data
    response.raise_for_status()
  File "/home/airflow/.local/lib/python3.8/site-packages/requests/models.py", line 1021, in raise_for_status
    raise HTTPError(http_error_msg, response=self)
requests.exceptions.HTTPError: 408 Client Error: Request Time-out for url: https://api.openaq.org/v2/locations?limit=2500

During handling of the above exception, another exception occurred:

Traceback (most recent call last):
  File "/home/airflow/.local/lib/python3.8/site-packages/airflow/operators/python.py", line 192, in execute
    return_value = self.execute_callable()
  File "/home/airflow/.local/lib/python3.8/site-packages/airflow/operators/python.py", line 209, in execute_callable
    return self.python_callable(*self.op_args, **self.op_kwargs)
  File "/opt/airflow/scripts/main.py", line 34, in load_locations
    json_api = get_data(base_url, endpoint, headers, params=params)
  File "/opt/airflow/scripts/utils.py", line 40, in get_data
    raise Exception(f"La peticion ha fallado. Codigo del error: {e}")
Exception: La peticion ha fallado. Codigo del error: 408 Client Error: Request Time-out for url: https://api.openaq.org/v2/locations?limit=2500
[2023-12-05T22:00:10.706+0000] {taskinstance.py:1400} INFO - Marking task as UP_FOR_RETRY. dag_id=dag_openaq, task_id=load_stations_data, execution_date=20231205T210000, start_date=20231205T220003, end_date=20231205T220010
[2023-12-05T22:00:10.721+0000] {standard_task_runner.py:104} ERROR - Failed to execute job 281 for task load_stations_data (La peticion ha fallado. Codigo del error: 408 Client Error: Request Time-out for url: https://api.openaq.org/v2/locations?limit=2500; 792)
[2023-12-05T22:00:10.744+0000] {local_task_job_runner.py:228} INFO - Task exited with return code 1
[2023-12-05T22:00:10.775+0000] {taskinstance.py:2778} INFO - 0 downstream tasks scheduled from follow-on schedule check
